Workbook

Sheet Instructions
B2: Software Bill of Materials (SBOM) — FDA 510(k) / Premarket Template (Enhanced Edition)
B3: Aligned with FDA guidance “Cybersecurity in Medical Devices: Quality Management System Considerations and Content of Premarket Submissions” (issued Feb 3, 2026), Section 524B of the FD&C Act, the NTIA Minimum Elements for an SBOM, and NIST SP 800-218 (SSDF). This edition adds the fields most commonly requested by FDA reviewers beyond the NTIA baseline, plus a self-checking compliance dashboard.
B5: IMPORTANT — Format of the Official Submission
B6: FDA requires a MACHINE-READABLE SBOM for cyber devices (industry-accepted formats such as CycloneDX or SPDX) in the eSTAR cybersecurity section of a 510(k). This Excel workbook is a human-readable WORKING / MANAGEMENT template and review companion — use it to assemble, track and review your component data, then generate the machine-readable SBOM your build tooling produces. It does not by itself replace the machine-readable file in the submission.
B8: What's in this workbook
B9: SBOM Metadata | C9: Device, submission, and SBOM document-level data — including the NTIA document-level elements (Author, Timestamp), manufacturer security/CVD contact, sign-off, and an Auto Summary that pulls live counts from the other tabs.
B10: SBOM Components | C10: The core component inventory: NTIA minimum elements, structured dependency classification, FDA risk-based prioritization fields (criticality, safety relevance, network exposure, authentication dependency, internet-facing), FDA lifecycle elements (support level, EOS/EOL with auto-calculated flags), and supply-chain integrity fields (hash, signature status, build/provenance ID).
B11: Environment & Third-Party Dependencies | C11: Operating system, container base image, embedded firmware, and third-party/cloud service dependencies — categories that sit outside the application component tree but are still part of the device's attack surface.
B12: Vulnerabilities & VEX | C12: Per-component known vulnerabilities with CVSS (version, base score, vector), EPSS score, CISA KEV status, VEX status and justification, patient-safety/clinical impact, exploitability, and a remediation plan with owner and target date.
B13: Lifecycle & Support Plan | C13: Obsolescence / end-of-support planning for components approaching or past EOS/EOL — risk, mitigation, compensating controls, verification method, owner and action dates.
B14: Supplier & Security Contact Registry | C14: One row per supplier/manufacturer with a security (PSIRT) contact and coordinated vulnerability disclosure (CVD) policy link — supports Sec. 524B's CVD and supply-chain transparency expectations.
B15: FDA Compliance Dashboard | C15: Self-checking traceability matrix: every NTIA/FDA element mapped to its location in this workbook, with a live completeness percentage computed from your data, plus a composite readiness indicator.
B17: Required / recommended SBOM fields — and where each lives
B18: Requirement | C18: Source / Location in this workbook
B19: Supplier Name | C19: NTIA min. element — SBOM Components, col. ‘Supplier / Legal Entity Name’
B20: Component Name | C20: NTIA min. element — SBOM Components, col. ‘Component Name’
B21: Version of the Component | C21: NTIA min. element — SBOM Components, col. ‘Version’
B22: Other Unique Identifiers | C22: NTIA min. element — SBOM Components, cols. ‘Unique ID Type’ + ‘Unique ID Value’ (CPE / PURL / SWID)
B23: Dependency Relationship | C23: NTIA min. element — SBOM Components, cols. ‘Dependency Type’, ‘Parent / Depends-On Component’, ‘Dependency Depth’ (structured, not free text)
B24: Author of SBOM Data | C24: NTIA min. element (document-level) — SBOM Metadata, ‘Author Name / Organization / Role / Email’
B25: Timestamp | C25: NTIA min. element (document-level) — SBOM Metadata, ‘SBOM Timestamp’
B26: Level of support | C26: FDA additional element (Sec. VII.C.3) — SBOM Components, col. ‘Level of Support’
B27: Component end-of-support (EOS) date | C27: FDA additional element (Sec. VII.C.3) — SBOM Components, col. ‘End-of-Support (EOS) Date’ (auto-flagged)
B28: End-of-life (EOL) date | C28: SBOM Components, col. ‘End-of-Life (EOL) Date’
B29: All known vulnerabilities | C29: FDA premarket expectation — Vulnerabilities & VEX tab
... B34: OS / container / firmware / third-party service dependencies | C34: Environment & Third-Party Dependencies tab
B36: How to use
B37: 1. Fill the SBOM Metadata tab first (device, submission, SBOM author/timestamp, manufacturer security contact).
B38: 2. Enter one row per component on the SBOM Components tab. The row shaded amber is an EXAMPLE — overwrite or delete it.
B39: 3. Use the drop-downs (Unique ID Type, Dependency Type, Component Type, Origin, Level of Support, Criticality, Network Exposure, VEX Status, etc.) for consistent, filterable values.
B40: 4. Enter EOS/EOL as real dates (YYYY-MM-DD). ‘Days to EOS’ and ‘Lifecycle Flag’ calculate automatically and turn red when a component is past support, amber within 12 months.
B41: 5. Log every known vulnerability on the Vulnerabilities & VEX tab; set a real VEX status (not left at ‘Under Investigation’ indefinitely) with justification, patient-safety impact, and a target date.
B42: 6. For any component near/past EOS, or with an unverified support status, complete a row on the Lifecycle & Support Plan tab.
B43: 7. Record every OS, container, firmware, or third-party service dependency on the Environment & Third-Party Dependencies tab — these are commonly missed but are part of the device's attack surface.
B44: 8. Add each supplier's security contact and CVD policy link to the Supplier & Security Contact Registry.
B45: 9. Check the FDA Compliance Dashboard tab before submission — it computes live completeness percentages from your data and flags anything still short of ‘Complete’.
B46: 10. Need more rows than pre-filled? Copy the last data row down — formulas, formatting, and validation carry over.
B48: Disclaimer: This template is a working aid, not regulatory or legal advice. FDA guidance is non-binding and evolves — verify current guidance and eSTAR requirements and consult your regulatory affairs function before submission.

Sheet SBOM Metadata
B2: SBOM Metadata
B4: Device & Submission
B5: Device Name | C5: Inference
B6: Device Model / Catalog Number | C6: Wellysis
B7: Manufacturer / Sponsor (Legal Entity Name) | C7: HCL
B8: Submission Type | C8: 510(k)
B9: Submission (e.g., 510(k)) Number | C9: 101
B10: Product Code / Regulation No. | C10: WL101
B11: Device Software Version | C11: 1.0.0
B12: Top-Level / Primary Component | C12: Inference
B14: SBOM Document (NTIA document-level elements)
B15: Author Name (Individual) [NTIA] | C15: hclcs.admin@hcltech.com
B16: Author Organization [NTIA]
B17: Author Role / Title
B18: Author Email
B19: SBOM Timestamp [NTIA] | C19: 46273.321
B20: SBOM Version | C20: 1.0.0
B21: SBOM Format(s) for Submission (e.g., CycloneDX / SPDX) | C21: SPDX
B22: SBOM Generation Tool & Version | C22: SNYK
B23: Primary Data Source | C23: Persisted SBOM analysis results
B25: Manufacturer Security Contact / Coordinated Vulnerability Disclosure
B26: Manufacturer PSIRT / Security Contact Email
B27: Coordinated Vulnerability Disclosure (CVD) Policy URL
B28: Vulnerability Intake Method (e.g., web form, email, HackerOne)
B30: Sign-off
B31: Prepared By | C31: hclcs.admin@hcltech.com
B32: Date Prepared | C32: 46273
B33: Reviewed / Approved By
B34: Date Approved | C34: 46273
B36: Auto Summary (live — calculated from other tabs, do not edit)
B37: Total components listed | C37: ='SBOM Components'!$AF$1 -> 28
B38: Components PAST end-of-support | C38: ='SBOM Components'!$AF$2 -> 0
B39: Components with EOS within 12 months | C39: ='SBOM Components'!$AF$3 -> 0
B40: Components no longer maintained / abandoned / unknown support | C40: ='SBOM Components'!$AF$4 -> 28
B41: Total vulnerabilities logged | C41: ='Vulnerabilities & VEX'!$V$1 -> 120
B42: Open Critical / High vulnerabilities | C42: ='Vulnerabilities & VEX'!$V$2 -> 14
B43: Vulnerabilities with no VEX justification yet | C43: ='Vulnerabilities & VEX'!$V$3 -> 120
B45: FDA Readiness Snapshot (full detail on 'FDA Compliance Dashboard' tab)
B46: Composite FDA Readiness Score (0-100%) | C46: ='FDA Compliance Dashboard'!$C$4 -> 0.34047619
B47: Readiness Status | C47: ='FDA Compliance Dashboard'!$D$4 -> Not Ready

Sheet SBOM Components
A1: NTIA Minimum Elements (Identification) | G1: Dependency & Classification | M1: Risk & Operational Classification (FDA Risk-Based Prioritization) | S1: FDA Lifecycle Elements (Sec. VII.C.3) — auto-calculated | X1: Vulnerabilities & Patching | Z1: Supply-Chain Integrity & Provenance | AD1: Notes | AE1: Total components (auto) | AF1: =COUNTA(B3:B500) -> 28
A2: # | B2: Component Name | C2: Version | D2: Supplier / Legal Entity Name | E2: Unique ID Type | F2: Unique ID Value | G2: Dependency Type | H2: Parent / Depends-On Component | I2: Dependency Depth | J2: Component Type | K2: Origin / Category | L2: License | M2: Runtime / Build-Time | N2: Criticality to Device Operation | O2: Safety Relevance | P2: Network Exposure | Q2: Authentication Dependency | R2: Internet-Facing | S2: Level of Support | T2: End-of-Support (EOS) Date | U2: End-of-Life (EOL) Date | V2: Days to EOS | W2: Lifecycle Flag | X2: Known Vulnerabilities (CVE/IDs) | Y2: Patch / Update Mechanism | Z2: Component Hash / Checksum (SHA-256) | AA2: Cryptographic Signature Status | AB2: Build Environment / Provenance ID | AC2: Supplier Security Contact (Email) | AD2: Notes / Justification | AE2: Past EOS (auto) | AF2: =COUNTIF(W3:W500,"*PAST EOS*") -> 0
A3: 1 | B3: certifi | C3: 2025.10.5 | D3: NOASSERTION | E3: PURL | F3: pkg:pypi/certifi@2025.10.5 | J3: Library | K3: Commercial (COTS) | L3: NOASSERTION | S3: Unknown | V3: =IF(T3="","",T3-TODAY()) | W3: =IF(T3="","",IF(T3<TODAY(),"PAST EOS — UNSUPPORTED",IF(T3-TODAY()<=365,"EOS within 12 months","Supported"))) | Y3: 2026.7.22 | AD3: Source SBOM(s): WSASBOM015_inference-fixed; DEPENDENCY_OF: requests | AF3: =COUNTIF(W3:W500,"*within 12*") -> 0
A4: 2 | B4: docker-image|sbom_inference.tar | D4: NOASSERTION | E4: Other | F4: SPDXRef-1-docker-image-sbom-inference.tar | J4: Library | K4: Commercial (COTS) | L4: NOASSERTION | S4: Unknown | V4: =IF(T4="","",T4-TODAY()) | W4: =IF(T4="","",IF(T4<TODAY(),"PAST EOS — UNSUPPORTED",IF(T4-TODAY()<=365,"EOS within 12 months","Supported"))) | AD4: Source SBOM(s): WSASBOM015_inference-fixed | AF4: =COUNTIF(S3:S500,"No longer maintained")+COUNTIF(S3:S500,"Abandoned")+COUNTIF(S3:S500,"Unknown") -> 28
A5: 3 | B5: filelock | C5: 3.20.0 | D5: NOASSERTION | E5: PURL | F5: pkg:pypi/filelock@3.20.0 | J5: Library | K5: Commercial (COTS) | L5: NOASSERTION | S5: Unknown | V5: =IF(T5="","",T5-TODAY()) | W5: =IF(T5="","",IF(T5<TODAY(),"PAST EOS — UNSUPPORTED",IF(T5-TODAY()<=365,"EOS within 12 months","Supported"))) | X5: CVE-2025-68146, CVE-2026-22701 | Y5: 3.32.5 | AD5: Source SBOM(s): WSASBOM015_inference-fixed; DEPENDENCY_OF: torch
A6: 4 | B6: fsspec | C6: 2026.6.0 | D6: NOASSERTION | E6: PURL | F6: pkg:pypi/fsspec@2026.6.0 | J6: Library | K6: Commercial (COTS) | L6: NOASSERTION | S6: Unknown | V6: =IF(T6="","",T6-TODAY()) | W6: =IF(T6="","",IF(T6<TODAY(),"PAST EOS — UNSUPPORTED",IF(T6-TODAY()<=365,"EOS within 12 months","Supported"))) | Y6: 2026.7.0 | AD6: Source SBOM(s): WSASBOM015_inference-fixed; DEPENDENCY_OF: torch
A7: 5 | B7: idna | C7: 3.11.0 | D7: NOASSERTION | E7: PURL | F7: pkg:pypi/idna@3.11.0 | J7: Library | K7: Commercial (COTS) | L7: NOASSERTION | S7: Unknown | V7: =IF(T7="","",T7-TODAY()) | W7: =IF(T7="","",IF(T7<TODAY(),"PAST EOS — UNSUPPORTED",IF(T7-TODAY()<=365,"EOS within 12 months","Supported"))) | X7: CVE-2026-45409 | Y7: 3.19 | AD7: Source SBOM(s): WSASBOM015_inference-fixed; DEPENDENCY_OF: requests
A8: 6 | B8: jinja2 | C8: 3.1.6 | D8: NOASSERTION | E8: PURL | F8: pkg:pypi/jinja2@3.1.6 | J8: Library | K8: Commercial (COTS) | L8: NOASSERTION | S8: Unknown | V8: =IF(T8="","",T8-TODAY()) | W8: =IF(T8="","",IF(T8<TODAY(),"PAST EOS — UNSUPPORTED",IF(T8-TODAY()<=365,"EOS within 12 months","Supported"))) | AD8: Source SBOM(s): WSASBOM015_inference-fixed; DEPENDENCY_OF: torch
A9: 7 | B9: joblib | C9: 1.5.3 | D9: NOASSERTION | E9: PURL | F9: pkg:pypi/joblib@1.5.3 | J9: Library | K9: Commercial (COTS) | L9: NOASSERTION | S9: Unknown | V9: =IF(T9="","",T9-TODAY()) | W9: =IF(T9="","",IF(T9<TODAY(),"PAST EOS — UNSUPPORTED",IF(T9-TODAY()<=365,"EOS within 12 months","Supported"))) | Y9: 1.6.0 | AD9: Source SBOM(s): WSASBOM015_inference-fixed; DEPENDENCY_OF: /models/requirements.txt
A10: 8 | B10: markupsafe | C10: 3.0.3 | D10: NOASSERTION | E10: PURL | F10: pkg:pypi/markupsafe@3.0.3 | J10: Library | K10: Commercial (COTS) | L10: NOASSERTION | S10: Unknown | V10: =IF(T10="","",T10-TODAY()) | W10: =IF(T10="","",IF(T10<TODAY(),"PAST EOS — UNSUPPORTED",IF(T10-TODAY()<=365,"EOS within 12 months","Supported"))) | AD10: Source SBOM(s): WSASBOM015_inference-fixed; DEPENDENCY_OF: jinja2
A11: 9 | B11: mpmath | C11: 1.3.0 | D11: NOASSERTION | E11: PURL | F11: pkg:pypi/mpmath@1.3.0 | J11: Library | K11: Commercial (COTS) | L11: NOASSERTION | S11: Unknown | V11: =IF(T11="","",T11-TODAY()) | W11: =IF(T11="","",IF(T11<TODAY(),"PAST EOS — UNSUPPORTED",IF(T11-TODAY()<=365,"EOS within 12 months","Supported"))) | Y11: 1.4.1 | AD11: Source SBOM(s): WSASBOM015_inference-fixed; DEPENDENCY_OF: sympy
A12: 10 | B12: networkx | C12: 3.6.1 | D12: NOASSERTION | E12: PURL | F12: pkg:pypi/networkx@3.6.1 | J12: Library | K12: Commercial (COTS) | L12: NOASSERTION | S12: Unknown | V12: =IF(T12="","",T12-TODAY()) | W12: =IF(T12="","",IF(T12<TODAY(),"PAST EOS — UNSUPPORTED",IF(T12-TODAY()<=365,"EOS within 12 months","Supported"))) | AD12: Source SBOM(s): WSASBOM015_inference-fixed; DEPENDENCY_OF: torch
A13: 11 | B13: neurokit2 | C13: 0.2.12 | D13: NOASSERTION | E13: PURL | F13: pkg:pypi/neurokit2@0.2.12 | J13: Library | K13: Commercial (COTS) | L13: NOASSERTION | S13: Unknown | V13: =IF(T13="","",T13-TODAY()) | W13: =IF(T13="","",IF(T13<TODAY(),"PAST EOS — UNSUPPORTED",IF(T13-TODAY()<=365,"EOS within 12 months","Supported"))) | Y13: 0.2.13 | AD13: Source SBOM(s): WSASBOM015_inference-fixed; DEPENDENCY_OF: /models/requirements.txt
A14: 12 | B14: oauthlib | C14: 3.3.1 | D14: NOASSERTION | E14: PURL | F14: pkg:pypi/oauthlib@3.3.1 | J14: Library | K14: Commercial (COTS) | L14: NOASSERTION | S14: Unknown | V14: =IF(T14="","",T14-TODAY()) | W14: =IF(T14="","",IF(T14<TODAY(),"PAST EOS — UNSUPPORTED",IF(T14-TODAY()<=365,"EOS within 12 months","Supported"))) | AD14: Source SBOM(s): WSASBOM015_inference-fixed; DEPENDENCY_OF: /models/requirements.txt
A15: 13 | B15: pandas | C15: 2.3.3 | D15: NOASSERTION | E15: PURL | F15: pkg:pypi/pandas@2.3.3 | J15: Library | K15: Commercial (COTS) | L15: NOASSERTION | S15: Unknown | V15: =IF(T15="","",T15-TODAY()) | W15: =IF(T15="","",IF(T15<TODAY(),"PAST EOS — UNSUPPORTED",IF(T15-TODAY()<=365,"EOS within 12 months","Supported"))) | Y15: 3.0.5 | AD15: Source SBOM(s): WSASBOM015_inference-fixed; DEPENDENCY_OF: /models/requirements.txt; DEPENDENCY_OF: neurokit2
A16: 14 | B16: pillow | C16: 11.3.0 | D16: NOASSERTION | E16: PURL | F16: pkg:pypi/pillow@11.3.0 | J16: Library | K16: Commercial (COTS) | L16: NOASSERTION | S16: Unknown | V16: =IF(T16="","",T16-TODAY()) | W16: =IF(T16="","",IF(T16<TODAY(),"PAST EOS — UNSUPPORTED",IF(T16-TODAY()<=365,"EOS within 12 months","Supported"))) | X16: CVE-2026-25990, CVE-2026-40192, CVE-2026-42308, CVE-2026-42309, CVE-2026-42310, CVE-2026-42311, CVE-2026-54058, CVE-2026-54059, CVE-2026-54060, CVE-2026-55379, CVE-2026-55380, CVE-2026-55798, CVE-2026-59197, CVE-2026-59198, CVE-2026-59199, CVE-2026-59200, CVE-2026-59204, CVE-2026-59205 | Y16: 12.3.0 | AD16: Source SBOM(s): WSASBOM015_inference-fixed; DEPENDENCY_OF: /models/requirements.txt
A17: 15 | B17: psutil | C17: 7.2.2 | D17: NOASSERTION | E17: PURL | F17: pkg:pypi/psutil@7.2.2 | J17: Library | K17: Commercial (COTS) | L17: NOASSERTION | S17: Unknown | V17: =IF(T17="","",T17-TODAY()) | W17: =IF(T17="","",IF(T17<TODAY(),"PAST EOS — UNSUPPORTED",IF(T17-TODAY()<=365,"EOS within 12 months","Supported"))) | AD17: Source SBOM(s): WSASBOM015_inference-fixed; DEPENDENCY_OF: /models/requirements.txt
A18: 16 | B18: pyjwt | C18: 2.13.0 | D18: NOASSERTION | E18: PURL | F18: pkg:pypi/pyjwt@2.13.0 | J18: Library | K18: Commercial (COTS) | L18: NOASSERTION | S18: Unknown | V18: =IF(T18="","",T18-TODAY()) | W18: =IF(T18="","",IF(T18<TODAY(),"PAST EOS — UNSUPPORTED",IF(T18-TODAY()<=365,"EOS within 12 months","Supported"))) | AD18: Source SBOM(s): WSASBOM015_inference-fixed; DEPENDENCY_OF: /models/requirements.txt
A19: 17 | B19: python-dateutil | C19: 2.9.0 | D19: NOASSERTION | E19: PURL | F19: pkg:pypi/python-dateutil@2.9.0 | J19: Library | K19: Commercial (COTS) | L19: NOASSERTION | S19: Unknown | V19: =IF(T19="","",T19-TODAY()) | W19: =IF(T19="","",IF(T19<TODAY(),"PAST EOS — UNSUPPORTED",IF(T19-TODAY()<=365,"EOS within 12 months","Supported"))) | Y19: 2.9.0.post0 | AD19: Source SBOM(s): WSASBOM015_inference-fixed; DEPENDENCY_OF: /models/requirements.txt; DEPENDENCY_OF: pandas
A20: 18 | B20: pytz | C20: 2025.2.0 | D20: NOASSERTION | E20: PURL | F20: pkg:pypi/pytz@2025.2.0 | J20: Library | K20: Commercial (COTS) | L20: NOASSERTION | S20: Unknown | V20: =IF(T20="","",T20-TODAY()) | W20: =IF(T20="","",IF(T20<TODAY(),"PAST EOS — UNSUPPORTED",IF(T20-TODAY()<=365,"EOS within 12 months","Supported"))) | Y20: 2026.3.post1 | AD20: Source SBOM(s): WSASBOM015_inference-fixed; DEPENDENCY_OF: /models/requirements.txt; DEPENDENCY_OF: pandas
A21: 19 | B21: pywavelets | C21: 1.9.0 | D21: NOASSERTION | E21: PURL | F21: pkg:pypi/pywavelets@1.9.0 | J21: Library | K21: Commercial (COTS) | L21: NOASSERTION | S21: Unknown | V21: =IF(T21="","",T21-TODAY()) | W21: =IF(T21="","",IF(T21<TODAY(),"PAST EOS — UNSUPPORTED",IF(T21-TODAY()<=365,"EOS within 12 months","Supported"))) | Y21: 1.10.0 | AD21: Source SBOM(s): WSASBOM015_inference-fixed; DEPENDENCY_OF: neurokit2
A22: 20 | B22: requests | C22: 2.34.2 | D22: NOASSERTION | E22: PURL | F22: pkg:pypi/requests@2.34.2 | J22: Library | K22: Commercial (COTS) | L22: NOASSERTION | S22: Unknown | V22: =IF(T22="","",T22-TODAY()) | W22: =IF(T22="","",IF(T22<TODAY(),"PAST EOS — UNSUPPORTED",IF(T22-TODAY()<=365,"EOS within 12 months","Supported"))) | AD22: Source SBOM(s): WSASBOM015_inference-fixed; DEPENDENCY_OF: neurokit2
A23: 21 | B23: requirements.txt | D23: NOASSERTION | E23: PURL | F23: pkg:pypi/models/requirements.txt | J23: Library | K23: Commercial (COTS) | L23: NOASSERTION | S23: Unknown | V23: =IF(T23="","",T23-TODAY()) | W23: =IF(T23="","",IF(T23<TODAY(),"PAST EOS — UNSUPPORTED",IF(T23-TODAY()<=365,"EOS within 12 months","Supported"))) | AD23: Source SBOM(s): WSASBOM015_inference-fixed
A24: 22 | B24: setuptools | C24: 82.0.1 | D24: NOASSERTION | E24: PURL | F24: pkg:pypi/setuptools@82.0.1 | J24: Library | K24: Commercial (COTS) | L24: NOASSERTION | S24: Unknown | V24: =IF(T24="","",T24-TODAY()) | W24: =IF(T24="","",IF(T24<TODAY(),"PAST EOS — UNSUPPORTED",IF(T24-TODAY()<=365,"EOS within 12 months","Supported"))) | X24: CVE-2026-59890 | Y24: 84.0.0 | AD24: Source SBOM(s): WSASBOM015_inference-fixed; DEPENDENCY_OF: /models/requirements.txt; DEPENDENCY_OF: torch
A25: 23 | B25: sympy | C25: 1.14.0 | D25: NOASSERTION | E25: PURL | F25: pkg:pypi/sympy@1.14.0 | J25: Library | K25: Commercial (COTS) | L25: NOASSERTION | S25: Unknown | V25: =IF(T25="","",T25-TODAY()) | W25: =IF(T25="","",IF(T25<TODAY(),"PAST EOS — UNSUPPORTED",IF(T25-TODAY()<=365,"EOS within 12 months","Supported"))) | AD25: Source SBOM(s): WSASBOM015_inference-fixed; DEPENDENCY_OF: torch
A26: 24 | B26: threadpoolctl | C26: 3.6.0 | D26: NOASSERTION | E26: PURL | F26: pkg:pypi/threadpoolctl@3.6.0 | J26: Library | K26: Commercial (COTS) | L26: NOASSERTION | S26: Unknown | V26: =IF(T26="","",T26-TODAY()) | W26: =IF(T26="","",IF(T26<TODAY(),"PAST EOS — UNSUPPORTED",IF(T26-TODAY()<=365,"EOS within 12 months","Supported"))) | AD26: Source SBOM(s): WSASBOM015_inference-fixed; DEPENDENCY_OF: /models/requirements.txt
A27: 25 | B27: torch | C27: 2.7.1 | D27: NOASSERTION | E27: PURL | F27: pkg:pypi/torch@2.7.1 | J27: Library | K27: Commercial (COTS) | L27: NOASSERTION | S27: Unknown | V27: =IF(T27="","",T27-TODAY()) | W27: =IF(T27="","",IF(T27<TODAY(),"PAST EOS — UNSUPPORTED",IF(T27-TODAY()<=365,"EOS within 12 months","Supported"))) | X27: CVE-2025-2999, CVE-2025-3000, CVE-2025-3001, CVE-2025-3730, CVE-2025-55551, CVE-2025-55552, CVE-2025-55554, CVE-2026-24747, CVE-2026-4538 | Y27: 2.14.0 | AD27: Source SBOM(s): WSASBOM015_inference-fixed; DEPENDENCY_OF: /models/requirements.txt
A28: 26 | B28: typing-extensions | C28: 4.15.0 | D28: NOASSERTION | E28: PURL | F28: pkg:pypi/typing-extensions@4.15.0 | J28: Library | K28: Commercial (COTS) | L28: NOASSERTION | S28: Unknown | V28: =IF(T28="","",T28-TODAY()) | W28: =IF(T28="","",IF(T28<TODAY(),"PAST EOS — UNSUPPORTED",IF(T28-TODAY()<=365,"EOS within 12 months","Supported"))) | Y28: 4.16.0 | AD28: Source SBOM(s): WSASBOM015_inference-fixed; DEPENDENCY_OF: pyjwt
A29: 27 | B29: tzdata | C29: 2026.3.0 | D29: NOASSERTION | E29: PURL | F29: pkg:pypi/tzdata@2026.3.0 | J29: Library | K29: Commercial (COTS) | L29: NOASSERTION | S29: Unknown | V29: =IF(T29="","",T29-TODAY()) | W29: =IF(T29="","",IF(T29<TODAY(),"PAST EOS — UNSUPPORTED",IF(T29-TODAY()<=365,"EOS within 12 months","Supported"))) | AD29: Source SBOM(s): WSASBOM015_inference-fixed; DEPENDENCY_OF: pandas
A30: 28 | B30: urllib3 | C30: 2.7.0 | D30: NOASSERTION | E30: PURL | F30: pkg:pypi/urllib3@2.7.0 | J30: Library | K30: Commercial (COTS) | L30: NOASSERTION | S30: Unknown | V30: =IF(T30="","",T30-TODAY()) | W30: =IF(T30="","",IF(T30<TODAY(),"PAST EOS — UNSUPPORTED",IF(T30-TODAY()<=365,"EOS within 12 months","Supported"))) | AD30: Source SBOM(s): WSASBOM015_inference-fixed; DEPENDENCY_OF: requests
V31: =IF(T31="","",T31-TODAY()) | W31: =IF(T31="","",IF(T31<TODAY(),"PAST EOS — UNSUPPORTED",IF(T31-TODAY()<=365,"EOS within 12 months","Supported")))
V32: =IF(T32="","",T32-TODAY()) | W32: =IF(T32="","",IF(T32<TODAY(),"PAST EOS — UNSUPPORTED",IF(T32-TODAY()<=365,"EOS within 12 months","Supported")))
V33: =IF(T33="","",T33-TODAY()) | W33: =IF(T33="","",IF(T33<TODAY(),"PAST EOS — UNSUPPORTED",IF(T33-TODAY()<=365,"EOS within 12 months","Supported")))
V34: =IF(T34="","",T34-TODAY()) | W34: =IF(T34="","",IF(T34<TODAY(),"PAST EOS — UNSUPPORTED",IF(T34-TODAY()<=365,"EOS within 12 months","Supported")))
V35: =IF(T35="","",T35-TODAY()) | W35: =IF(T35="","",IF(T35<TODAY(),"PAST EOS — UNSUPPORTED",IF(T35-TODAY()<=365,"EOS within 12 months","Supported")))
V36: =IF(T36="","",T36-TODAY()) | W36: =IF(T36="","",IF(T36<TODAY(),"PAST EOS — UNSUPPORTED",IF(T36-TODAY()<=365,"EOS within 12 months","Supported")))
V37: =IF(T37="","",T37-TODAY()) | W37: =IF(T37="","",IF(T37<TODAY(),"PAST EOS — UNSUPPORTED",IF(T37-TODAY()<=365,"EOS within 12 months","Supported")))
V38: =IF(T38="","",T38-TODAY()) | W38: =IF(T38="","",IF(T38<TODAY(),"PAST EOS — UNSUPPORTED",IF(T38-TODAY()<=365,"EOS within 12 months","Supported")))
V39: =IF(T39="","",T39-TODAY()) | W39: =IF(T39="","",IF(T39<TODAY(),"PAST EOS — UNSUPPORTED",IF(T39-TODAY()<=365,"EOS within 12 months","Supported")))
V40: =IF(T40="","",T40-TODAY()) | W40: =IF(T40="","",IF(T40<TODAY(),"PAST EOS — UNSUPPORTED",IF(T40-TODAY()<=365,"EOS within 12 months","Supported")))
...

Sheet Environment & 3rd-Party Deps
A1: OS / Container / Firmware / Third-Party Service Dependencies — components outside the application dependency tree that are still part of the device's attack surface
A2: # | B2: Dependency Category | C2: Name | D2: Version / Tag / Digest | E2: Supplier / Vendor | F2: Unique Identifier (PURL / Image Digest / CPE) | G2: Level of Support | H2: EOS Date | I2: EOL Date | J2: Known Vulnerabilities | K2: Network Exposure | L2: Notes
A3: 1 | B3: Operating System | C3: acl/libacl1 | D3: 2.3.2-1build1.1 | E3: NOASSERTION | F3: pkg:deb/ubuntu/libacl1@2.3.2-1build1.1?distro=ubuntu-24.04&upstream=acl | G3: Actively maintained | H3: 49059 | I3: 47269 | L3: WSASBOM015_inference-fixed
A4: 2 | B4: Operating System | C4: adduser | D4: 3.137ubuntu1 | E4: NOASSERTION | F4: pkg:deb/ubuntu/adduser@3.137ubuntu1?distro=ubuntu-24.04 | G4: Actively maintained | H4: 49059 | I4: 47269 | L4: WSASBOM015_inference-fixed
A5: 3 | B5: Operating System | C5: apt | D5: 2.8.3 | E5: NOASSERTION | F5: pkg:deb/ubuntu/apt@2.8.3?distro=ubuntu-24.04 | G5: Actively maintained | H5: 49059 | I5: 47269 | L5: WSASBOM015_inference-fixed
A6: 4 | B6: Operating System | C6: apt/apt-utils | D6: 2.8.3 | E6: NOASSERTION | F6: pkg:deb/ubuntu/apt-utils@2.8.3?distro=ubuntu-24.04&upstream=apt | G6: Actively maintained | H6: 49059 | I6: 47269 | L6: WSASBOM015_inference-fixed
A7: 5 | B7: Operating System | C7: apt/libapt-pkg6.0t64 | D7: 2.8.3 | E7: NOASSERTION | F7: pkg:deb/ubuntu/libapt-pkg6.0t64@2.8.3?distro=ubuntu-24.04&upstream=apt | G7: Actively maintained | H7: 49059 | I7: 47269 | L7: WSASBOM015_inference-fixed
A8: 6 | B8: Operating System | C8: attr/libattr1 | D8: 1:2.5.2-1build1.1 | E8: NOASSERTION | F8: pkg:deb/ubuntu/libattr1@1:2.5.2-1build1.1?distro=ubuntu-24.04&upstream=attr | G8: Actively maintained | H8: 49059 | I8: 47269 | L8: WSASBOM015_inference-fixed
A9: 7 | B9: Operating System | C9: audit/libaudit-common | D9: 1:3.1.2-2.1build1.1 | E9: NOASSERTION | F9: pkg:deb/ubuntu/libaudit-common@1:3.1.2-2.1build1.1?distro=ubuntu-24.04&upstream=audit | G9: Actively maintained | H9: 49059 | I9: 47269 | L9: WSASBOM015_inference-fixed
A10: 8 | B10: Operating System | C10: audit/libaudit1 | D10: 1:3.1.2-2.1build1.1 | E10: NOASSERTION | F10: pkg:deb/ubuntu/libaudit1@1:3.1.2-2.1build1.1?distro=ubuntu-24.04&upstream=audit | G10: Actively maintained | H10: 49059 | I10: 47269 | L10: WSASBOM015_inference-fixed
A11: 9 | B11: Operating System | C11: base-files | D11: 13ubuntu10.4 | E11: NOASSERTION | F11: pkg:deb/ubuntu/base-files@13ubuntu10.4?distro=ubuntu-24.04 | G11: Actively maintained | H11: 49059 | I11: 47269 | L11: WSASBOM015_inference-fixed
A12: 10 | B12: Operating System | C12: base-passwd | D12: 3.6.3build1 | E12: NOASSERTION | F12: pkg:deb/ubuntu/base-passwd@3.6.3build1?distro=ubuntu-24.04 | G12: Actively maintained | H12: 49059 | I12: 47269 | L12: WSASBOM015_inference-fixed
A13: 11 | B13: Operating System | C13: bash | D13: 5.2.21-2ubuntu4 | E13: NOASSERTION | F13: pkg:deb/ubuntu/bash@5.2.21-2ubuntu4?distro=ubuntu-24.04 | G13: Actively maintained | H13: 49059 | I13: 47269 | L13: WSASBOM015_inference-fixed
A14: 12 | B14: Operating System | C14: binutils/binutils-common | D14: 2.42-4ubuntu2.10 | E14: NOASSERTION | F14: pkg:deb/ubuntu/binutils-common@2.42-4ubuntu2.10?distro=ubuntu-24.04&upstream=binutils | G14: Actively maintained | H14: 49059 | I14: 47269 | L14: WSASBOM015_inference-fixed
... A18: 16 | B18: Operating System | C18: cdebconf/libdebconfclient0 | D18: 0.271ubuntu3 | E18: NOASSERTION | F18: pkg:deb/ubuntu/libdebconfclient0@0.271ubuntu3?distro=ubuntu-24.04&upstream=cdebconf | G18: Actively maintained | H18: 49059 | I18: 47269 | L18: WSASBOM015_inference-fixed
A19: 17 | B19: Operating System | C19: coreutils | D19: 9.4-3ubuntu6.2 | E19: NOASSERTION | F19: pkg:deb/ubuntu/coreutils@9.4-3ubuntu6.2?distro=ubuntu-24.04 | G19: Actively maintained | H19: 49059 | I19: 47269 | J19: UBUNTU-CVE-2016-2781, UBUNTU-CVE-2025-5278, USN-8697-1 | L19: WSASBOM015_inference-fixed
A20: 18 | B20: Operating System | C20: cuda-cccl/cuda-cccl-13-0 | D20: 13.0.85-1 | E20: NOASSERTION | F20: pkg:deb/ubuntu/cuda-cccl-13-0@13.0.85-1?distro=ubuntu-24.04&upstream=cuda-cccl | G20: Actively maintained | H20: 49059 | I20: 47269 | L20: WSASBOM015_inference-fixed
A21: 19 | B21: Operating System | C21: cuda-cudart/cuda-cudart-13-0 | D21: 13.0.96-1 | E21: NOASSERTION | F21: pkg:deb/ubuntu/cuda-cudart-13-0@13.0.96-1?distro=ubuntu-24.04&upstream=cuda-cudart | G21: Actively maintained | H21: 49059 | I21: 47269 | L21: WSASBOM015_inference-fixed
A22: 20 | B22: Operating System | C22: cuda-cudart/cuda-cudart-dev-13-0 | D22: 13.0.96-1 | E22: NOASSERTION | F22: pkg:deb/ubuntu/cuda-cudart-dev-13-0@13.0.96-1?distro=ubuntu-24.04&upstream=cuda-cudart | G22: Actively maintained | H22: 49059 | I22: 47269 | L22: WSASBOM015_inference-fixed
A23: 21 | B23: Operating System | C23: cuda-cudart/cuda-driver-dev-13-0 | D23: 13.0.96-1 | E23: NOASSERTION | F23: pkg:deb/ubuntu/cuda-driver-dev-13-0@13.0.96-1?distro=ubuntu-24.04&upstream=cuda-cudart | G23: Actively maintained | H23: 49059 | I23: 47269 | L23: WSASBOM015_inference-fixed
A24: 22 | B24: Operating System | C24: cuda-cudart/cuda-toolkit-13-0-config-common | D24: 13.0.96-1 | E24: NOASSERTION | F24: pkg:deb/ubuntu/cuda-toolkit-13-0-config-common@13.0.96-1?distro=ubuntu-24.04&upstream=cuda-cudart | G24: Actively maintained | H24: 49059 | I24: 47269 | L24: WSASBOM015_inference-fixed
A25: 23 | B25: Operating System | C25: cuda-cudart/cuda-toolkit-13-config-common | D25: 13.3.29-1 | E25: NOASSERTION | F25: pkg:deb/ubuntu/cuda-toolkit-13-config-common@13.3.29-1?distro=ubuntu-24.04&upstream=cuda-cudart | G25: Actively maintained | H25: 49059 | I25: 47269 | L25: WSASBOM015_inference-fixed
A26: 24 | B26: Operating System | C26: cuda-cudart/cuda-toolkit-config-common | D26: 13.3.29-1 | E26: NOASSERTION | F26: pkg:deb/ubuntu/cuda-toolkit-config-common@13.3.29-1?distro=ubuntu-24.04&upstream=cuda-cudart | G26: Actively maintained | H26: 49059 | I26: 47269 | L26: WSASBOM015_inference-fixed
A27: 25 | B27: Operating System | C27: cuda-culibos/cuda-culibos-13-0 | D27: 13.0.85-1 | E27: NOASSERTION | F27: pkg:deb/ubuntu/cuda-culibos-13-0@13.0.85-1?distro=ubuntu-24.04&upstream=cuda-culibos | G27: Actively maintained | H27: 49059 | I27: 47269 | L27: WSASBOM015_inference-fixed
A28: 26 | B28: Operating System | C28: cuda-culibos/cuda-culibos-dev-13-0 | D28: 13.0.85-1 | E28: NOASSERTION | F28: pkg:deb/ubuntu/cuda-culibos-dev-13-0@13.0.85-1?distro=ubuntu-24.04&upstream=cuda-culibos | G28: Actively maintained | H28: 49059 | I28: 47269 | L28: WSASBOM015_inference-fixed
A29: 27 | B29: Operating System | C29: cuda-cuobjdump/cuda-cuobjdump-13-0 | D29: 13.0.85-1 | E29: NOASSERTION | F29: pkg:deb/ubuntu/cuda-cuobjdump-13-0@13.0.85-1?distro=ubuntu-24.04&upstream=cuda-cuobjdump | G29: Actively maintained | H29: 49059 | I29: 47269 | L29: WSASBOM015_inference-fixed
A30: 28 | B30: Operating System | C30: cuda-cupti/cuda-cupti-13-0 | D30: 13.0.85-1 | E30: NOASSERTION | F30: pkg:deb/ubuntu/cuda-cupti-13-0@13.0.85-1?distro=ubuntu-24.04&upstream=cuda-cupti | G30: Actively maintained | H30: 49059 | I30: 47269 | L30: WSASBOM015_inference-fixed
A31: 29 | B31: Operating System | C31: cuda-cupti/cuda-cupti-dev-13-0 | D31: 13.0.85-1 | E31: NOASSERTION | F31: pkg:deb/ubuntu/cuda-cupti-dev-13-0@13.0.85-1?distro=ubuntu-24.04&upstream=cuda-cupti | G31: Actively maintained | H31: 49059 | I31: 47269 | L31: WSASBOM015_inference-fixed
... A42: 40 | B42: Operating System | C42: cudnn/libcudnn9-headers-cuda-13 | D42: 9.24.0.43-1 | E42: NOASSERTION | F42: pkg:deb/ubuntu/libcudnn9-headers-cuda-13@9.24.0.43-1?distro=ubuntu-24.04&upstream=cudnn | G42: Actively maintained | H42: 49059 | I42: 47269 | L42: WSASBOM015_inference-fixed
A43: 41 | B43: Operating System | C43: curl | D43: 8.5.0-2ubuntu10.11 | E43: NOASSERTION | F43: pkg:deb/ubuntu/curl@8.5.0-2ubuntu10.11?distro=ubuntu-24.04 | G43: Actively maintained | H43: 49059 | I43: 47269 | J43: UBUNTU-CVE-2026-11856, UBUNTU-CVE-2026-13608, UBUNTU-CVE-2026-18924, UBUNTU-CVE-2026-19931, UBUNTU-CVE-2026-80229, UBUNTU-CVE-2026-80230, UBUNTU-CVE-2026-80231, UBUNTU-CVE-2026-80255, UBUNTU-CVE-2026-82208, UBUNTU-CVE-2026-82209, UBUNTU-CVE-2026-8932, USN-8651-1, USN-8670-1 | L43: WSASBOM015_inference-fixed
A44: 42 | B44: Operating System | C44: curl/libcurl4-openssl-dev | D44: 8.5.0-2ubuntu10.11 | E44: NOASSERTION | F44: pkg:deb/ubuntu/libcurl4-openssl-dev@8.5.0-2ubuntu10.11?distro=ubuntu-24.04&upstream=curl | G44: Actively maintained | H44: 49059 | I44: 47269 | L44: WSASBOM015_inference-fixed
A45: 43 | B45: Operating System | C45: curl/libcurl4t64 | D45: 8.5.0-2ubuntu10.11 | E45: NOASSERTION | F45: pkg:deb/ubuntu/libcurl4t64@8.5.0-2ubuntu10.11?distro=ubuntu-24.04&upstream=curl | G45: Actively maintained | H45: 49059 | I45: 47269 | L45: WSASBOM015_inference-fixed
A46: 44 | B46: Operating System | C46: cyrus-sasl2/libsasl2-2 | D46: 2.1.28+dfsg1-5ubuntu3.1 | E46: NOASSERTION | F46: pkg:deb/ubuntu/libsasl2-2@2.1.28%2Bdfsg1-5ubuntu3.1?distro=ubuntu-24.04&upstream=cyrus-sasl2 | G46: Actively maintained | H46: 49059 | I46: 47269 | L46: WSASBOM015_inference-fixed
A47: 45 | B47: Operating System | C47: cyrus-sasl2/libsasl2-modules-db | D47: 2.1.28+dfsg1-5ubuntu3.1 | E47: NOASSERTION | F47: pkg:deb/ubuntu/libsasl2-modules-db@2.1.28%2Bdfsg1-5ubuntu3.1?distro=ubuntu-24.04&upstream=cyrus-sasl2 | G47: Actively maintained | H47: 49059 | I47: 47269 | L47: WSASBOM015_inference-fixed
A48: 46 | B48: Operating System | C48: dash | D48: 0.5.12-6ubuntu5 | E48: NOASSERTION | F48: pkg:deb/ubuntu/dash@0.5.12-6ubuntu5?distro=ubuntu-24.04 | G48: Actively maintained | H48: 49059 | I48: 47269 | L48: WSASBOM015_inference-fixed
A49: 47 | B49: Operating System | C49: datacenter-gpu-manager-4-core | D49: 1:4.6.0-1 | E49: NOASSERTION | F49: pkg:deb/ubuntu/datacenter-gpu-manager-4-core@1:4.6.0-1?distro=ubuntu-24.04 | G49: Actively maintained | H49: 49059 | I49: 47269 | L49: WSASBOM015_inference-fixed
A50: 48 | B50: Operating System | C50: datacenter-gpu-manager-4-dev | D50: 1:4.6.0-1 | E50: NOASSERTION | F50: pkg:deb/ubuntu/datacenter-gpu-manager-4-dev@1:4.6.0-1?distro=ubuntu-24.04 | G50: Actively maintained | H50: 49059 | I50: 47269 | L50: WSASBOM015_inference-fixed
A51: 49 | B51: Operating System | C51: db5.3/libdb5.3t64 | D51: 5.3.28+dfsg2-7 | E51: NOASSERTION | F51: pkg:deb/ubuntu/libdb5.3t64@5.3.28%2Bdfsg2-7?distro=ubuntu-24.04&upstream=db5.3 | G51: Actively maintained | H51: 49059 | I51: 47269 | L51: WSASBOM015_inference-fixed
A52: 50 | B52: Operating System | C52: dbus/libdbus-1-dev | D52: 1.14.10-4ubuntu4.1 | E52: NOASSERTION | F52: pkg:deb/ubuntu/libdbus-1-dev@1.14.10-4ubuntu4.1?distro=ubuntu-24.04&upstream=dbus | G52: Actively maintained | H52: 49059 | I52: 47269 | L52: WSASBOM015_inference-fixed
A53: 51 | B53: Operating System | C53: debconf | D53: 1.5.86ubuntu1 | E53: NOASSERTION | F53: pkg:deb/ubuntu/debconf@1.5.86ubuntu1?distro=ubuntu-24.04 | G53: Actively maintained | H53: 49059 | I53: 47269 | L53: WSASBOM015_inference-fixed
...

Sheet Vulnerabilities & VEX
A1: Identification | E1: Severity Scoring | I1: Threat Intelligence | K1: VEX & Safety Assessment | O1: Remediation Plan | S1: Status & Notes | U1: Total vulns (auto) | V1: =COUNTA(D3:D500) -> 120
A2: # | B2: Component Name | C2: Component Version | D2: Vulnerability ID (CVE/GHSA) | E2: CVSS Version | F2: CVSS Base Score | G2: CVSS Vector | H2: Severity | I2: EPSS Score | J2: CISA KEV Status | K2: VEX Status | L2: VEX Justification | M2: Patient Safety / Clinical Impact | N2: Exploitability | O2: Remediation / Mitigation Plan | P2: Fixed / Target Version(s) | Q2: Remediation Owner | R2: Target / Resolution Date | S2: Status | T2: Notes | U2: Open Crit/High (auto) | V2: =COUNTIFS(H3:H500,"Critical",S3:S500,"Open")+COUNTIFS(H3:H500,"High",S3:S500,"Open") -> 14
A3: 1 | B3: torch | C3: 2.7.1 | D3: CVE-2025-2999 | G3: AV:L/AC:L/PR:L/UI:N/S:U/C:L/I:L/A:L | H3: Medium | I3: 0.00198 | J3: No | K3: Under Investigation | P3: 2.9.1 | S3: Open | T3: OSV | V3: =COUNTIFS(D3:D500,"<>",L3:L500,"") -> 120
A4: 2 | B4: torch | C4: 2.7.1 | D4: CVE-2025-3000 | G4: AV:L/AC:L/PR:L/UI:N/S:U/C:L/I:L/A:L | H4: Low | I4: 0.00199 | J4: No | K4: Under Investigation | P4: 2.13.0 | S4: Open | T4: OSV | V4: =COUNTIF(K3:K500,"Under Investigation") -> 120
A5: 3 | B5: torch | C5: 2.7.1 | D5: CVE-2025-3001 | G5: AV:L/AC:L/PR:L/UI:N/S:U/C:L/I:L/A:L | H5: Low | I5: 0.00198 | J5: No | K5: Under Investigation | P5: 2.10.0 | S5: Open | T5: OSV | V5: =COUNTIFS(D3:D500,"<>",F3:F500,"") -> 119
A6: 4 | B6: torch | C6: 2.7.1 | D6: CVE-2025-3730 | G6: AV:L/AC:L/PR:L/UI:N/S:U/C:N/I:N/A:L | H6: Medium | I6: 0.00317 | J6: No | K6: Under Investigation | P6: 2.8.0 | S6: Open | T6: OSV | V6: =COUNTIFS(D3:D500,"<>",R3:R500,"") -> 120
A7: 5 | B7: torch | C7: 2.7.1 | D7: CVE-2025-55551 | G7: AV:N/AC:L/PR:N/UI:N/S:U/C:N/I:N/A:H | H7: Unknown | I7: 0.00423 | J7: No | K7: Under Investigation | P7: 2.9.0 | S7: Open | T7: OSV
A8: 6 | B8: torch | C8: 2.7.1 | D8: CVE-2025-55552 | G8: AV:N/AC:L/PR:N/UI:N/S:U/C:N/I:N/A:H | H8: Unknown | I8: 0.00418 | J8: No | K8: Under Investigation | P8: 2.9.0 | S8: Open | T8: OSV
A9: 7 | B9: torch | C9: 2.7.1 | D9: CVE-2025-55554 | G9: AV:N/AC:L/PR:N/UI:N/S:U/C:N/I:N/A:L | H9: Unknown | I9: 0.00315 | J9: No | K9: Under Investigation | P9: 2.9.0 | S9: Open | T9: OSV
A10: 8 | B10: filelock | C10: 3.20.0 | D10: CVE-2025-68146 | G10: AV:L/AC:H/PR:L/UI:N/S:U/C:N/I:H/A:H | H10: Medium | I10: 0.00201 | J10: No | K10: Under Investigation | P10: 3.20.1 | S10: Open | T10: OSV
A11: 9 | B11: filelock | C11: 3.20.0 | D11: CVE-2026-22701 | G11: AV:L/AC:H/PR:L/UI:N/S:U/C:N/I:L/A:H | H11: Medium | I11: 0.00128 | J11: No | K11: Under Investigation | P11: 3.20.3 | S11: Open | T11: OSV
A12: 10 | B12: torch | C12: 2.7.1 | D12: CVE-2026-24747 | G12: AV:N/AC:L/PR:N/UI:R/S:U/C:H/I:H/A:H | H12: Unknown | I12: 0.00706 | J12: No | K12: Under Investigation | P12: 2.10.0 | S12: Open | T12: OSV
A13: 11 | B13: pillow | C13: 11.3.0 | D13: CVE-2026-25990 | G13: AV:L/AC:L/AT:N/PR:N/UI:N/VC:H/VI:H/VA:H/SC:N/SI:N/SA:N | H13: High | I13: 0.00367 | J13: No | K13: Under Investigation | P13: 12.1.1 | S13: Open | T13: NVD,OSV
A14: 12 | B14: pillow | C14: 11.3.0 | D14: CVE-2026-40192 | G14: AV:N/AC:L/PR:N/UI:N/S:U/C:N/I:N/A:H | H14: High | I14: 0.00671 | J14: No | K14: Under Investigation | P14: 12.2.0 | S14: Open | T14: NVD,OSV
A15: 13 | B15: pillow | C15: 11.3.0 | D15: CVE-2026-42308 | G15: AV:L/AC:L/PR:L/UI:N/S:U/C:N/I:N/A:H | H15: Medium | I15: 0.00114 | J15: No | K15: Under Investigation | P15: 12.2.0 | S15: Open | T15: NVD,OSV
A16: 14 | B16: pillow | C16: 11.3.0 | D16: CVE-2026-42309 | G16: AV:L/AC:L/PR:L/UI:N/S:U/C:N/I:N/A:H | H16: Medium | I16: 0.00133 | J16: No | K16: Under Investigation | P16: 12.2.0 | S16: Open | T16: NVD,OSV
A17: 15 | B17: pillow | C17: 11.3.0 | D17: CVE-2026-42310 | G17: AV:L/AC:L/PR:L/UI:N/S:U/C:N/I:N/A:H | H17: Medium | I17: 0.00126 | J17: No | K17: Under Investigation | P17: 12.2.0 | S17: Open | T17: NVD,OSV
A18: 16 | B18: pillow | C18: 11.3.0 | D18: CVE-2026-42311 | G18: AV:L/AC:L/AT:N/PR:N/UI:N/VC:H/VI:H/VA:H/SC:N/SI:N/SA:N | H18: High | I18: 0.0015 | J18: No | K18: Under Investigation | P18: 12.2.0 | S18: Open | T18: NVD,OSV
A19: 17 | B19: torch | C19: 2.7.1 | D19: CVE-2026-4538 | G19: AV:L/AC:L/PR:L/UI:N/S:U/C:H/I:H/A:H | H19: Unknown | I19: 0.00239 | J19: No | K19: Under Investigation | S19: Open | T19: OSV
A20: 18 | B20: idna | C20: 3.11.0 | D20: CVE-2026-45409 | G20: AV:N/AC:L/PR:N/UI:N/S:U/C:N/I:N/A:L | H20: Medium | I20: 0.00408 | J20: No | K20: Under Investigation | P20: 3.15 | S20: Open | T20: OSV
A21: 19 | B21: pillow | C21: 11.3.0 | D21: CVE-2026-54058 | G21: AV:N/AC:L/AT:P/PR:N/UI:N/VC:H/VI:N/VA:H/SC:N/SI:N/SA:N | H21: High | I21: 0.00521 | J21: No | K21: Under Investigation | P21: 12.3.0 | S21: Open | T21: NVD,OSV
A22: 20 | B22: pillow | C22: 11.3.0 | D22: CVE-2026-54059 | G22: AV:N/AC:L/PR:N/UI:N/S:U/C:N/I:N/A:H | H22: High | I22: 0.0041 | J22: No | K22: Under Investigation | P22: 12.3.0 | S22: Open | T22: NVD,OSV
A23: 21 | B23: pillow | C23: 11.3.0 | D23: CVE-2026-54060 | G23: AV:N/AC:L/PR:N/UI:N/S:U/C:N/I:N/A:H | H23: High | I23: 0.00418 | J23: No | K23: Under Investigation | P23: 12.3.0 | S23: Open | T23: NVD,OSV
A24: 22 | B24: pillow | C24: 11.3.0 | D24: CVE-2026-55379 | G24: AV:N/AC:L/PR:N/UI:N/S:U/C:N/I:N/A:H | H24: High | I24: 0.00421 | J24: No | K24: Under Investigation | P24: 12.3.0 | S24: Open | T24: NVD,OSV
A25: 23 | B25: pillow | C25: 11.3.0 | D25: CVE-2026-55380 | G25: AV:N/AC:L/PR:N/UI:N/S:U/C:N/I:N/A:H | H25: High | I25: 0.00418 | J25: No | K25: Under Investigation | P25: 12.3.0 | S25: Open | T25: NVD,OSV
A26: 24 | B26: pillow | C26: 11.3.0 | D26: CVE-2026-55798 | G26: AV:L/AC:H/PR:N/UI:R/S:U/C:L/I:L/A:L | H26: Medium | I26: 0.00179 | J26: No | K26: Under Investigation | P26: 12.3.0 | S26: Open | T26: NVD,OSV
A27: 25 | B27: pillow | C27: 11.3.0 | D27: CVE-2026-59197 | G27: AV:N/AC:L/PR:N/UI:N/S:U/C:N/I:L/A:H | H27: High | I27: 0.00445 | J27: No | K27: Under Investigation | P27: 12.3.0 | S27: Open | T27: NVD,OSV
A28: 26 | B28: pillow | C28: 11.3.0 | D28: CVE-2026-59198 | F28: 7.5 | G28: AV:N/AC:H/PR:N/UI:N/S:U/C:H/I:N/A:L | H28: High | I28: 0.00325 | J28: No | K28: Under Investigation | P28: 12.3.0 | S28: Open | T28: NVD,OSV
A29: 27 | B29: pillow | C29: 11.3.0 | D29: CVE-2026-59199 | G29: AV:N/AC:L/PR:N/UI:N/S:U/C:N/I:N/A:H | H29: High | I29: 0.00385 | J29: No | K29: Under Investigation | P29: 12.3.0 | S29: Open | T29: NVD,OSV
A30: 28 | B30: pillow | C30: 11.3.0 | D30: CVE-2026-59200 | G30: AV:N/AC:L/PR:N/UI:N/S:U/C:N/I:N/A:H | H30: High | I30: 0.00385 | J30: No | K30: Under Investigation | P30: 12.3.0 | S30: Open | T30: NVD,OSV
A31: 29 | B31: pillow | C31: 11.3.0 | D31: CVE-2026-59204 | G31: AV:N/AC:L/AT:N/PR:N/UI:N/VC:N/VI:N/VA:H/SC:N/SI:N/SA:N | H31: High | I31: 0.00393 | J31: No | K31: Under Investigation | P31: 12.3.0 | S31: Open | T31: NVD,OSV
A32: 30 | B32: pillow | C32: 11.3.0 | D32: CVE-2026-59205 | G32: AV:N/AC:L/PR:N/UI:N/S:U/C:N/I:N/A:H | H32: High | I32: 0.00385 | J32: No | K32: Under Investigation | P32: 12.3.0 | S32: Open | T32: NVD,OSV
A33: 31 | B33: setuptools | C33: 82.0.1 | D33: CVE-2026-59890 | G33: AV:L/AC:L/PR:N/UI:R/S:U/C:H/I:L/A:N | H33: Medium | I33: 0.00405 | J33: No | K33: Under Investigation | P33: 83.0.0 | S33: Open | T33: OSV
A34: 32 | B34: coreutils | C34: 9.4-3ubuntu6.2 | D34: UBUNTU-CVE-2016-2781 | G34: AV:L/AC:L/PR:L/UI:N/S:C/C:N/I:H/A:N | H34: Unknown | J34: No | K34: Under Investigation | S34: Open | T34: OSV
A35: 33 | B35: git | C35: 1:2.43.0-1ubuntu7.3 | D35: UBUNTU-CVE-2018-1000021 | G35: AV:N/AC:H/PR:N/UI:R/S:U/C:L/I:L/A:L | H35: Unknown | J35: No | K35: Under Investigation | S35: Open | T35: OSV
A36: 34 | B36: wget | C36: 1.21.4-1ubuntu4.3 | D36: UBUNTU-CVE-2021-31879 | G36: AV:N/AC:L/PR:N/UI:R/S:C/C:L/I:L/A:N | H36: Unknown | J36: No | K36: Under Investigation | S36: Open | T36: OSV
A37: 35 | B37: wget | C37: 1.21.4-1ubuntu4.3 | D37: UBUNTU-CVE-2024-10524 | G37: AV:N/AC:H/PR:N/UI:N/S:C/C:L/I:L/A:L | H37: Unknown | J37: No | K37: Under Investigation | S37: Open | T37: OSV
A38: 36 | B38: libgcrypt11 | D38: UBUNTU-CVE-2024-2236 | G38: AV:N/AC:H/PR:N/UI:N/S:U/C:H/I:N/A:N | H38: Unknown | J38: No | K38: Under Investigation | P38: 1.10.3-2ubuntu0.2, 1.12.0-2ubuntu1.1, 1.9.4-3ubuntu3.3 | S38: Open | T38: OSV
A39: 37 | B39: git | C39: 1:2.43.0-1ubuntu7.3 | D39: UBUNTU-CVE-2024-52005 | G39: AV:N/AC:H/AT:N/PR:N/UI:A/VC:H/VI:H/VA:H/SC:N/SI:N/SA:N | H39: Unknown | J39: No | K39: Under Investigation | S39: Open | T39: OSV
A40: 38 | B40: python2.7 | D40: UBUNTU-CVE-2025-12781 | G40: AV:N/AC:H/AT:P/PR:N/UI:N/VC:N/VI:L/VA:N/SC:N/SI:N/SA:N | H40: Unknown | J40: No | K40: Under Investigation | S40: Open | T40: OSV
...

Sheet Lifecycle & Support Plan
A1: End-of-Support / End-of-Life Planning — for every component near/past EOS or whose support status is unverified
A2: # | B2: Component Name | C2: Version | D2: Supplier | E2: Support Level | F2: EOS Date | G2: EOL Date | H2: Days to EOS | I2: Risk if Unsupported | J2: Mitigation / Replacement Plan | K2: Compensating Controls | L2: Verification Method | M2: Owner / Responsible | N2: Target Action Date | O2: Status
A3: 1 | B3: acl/libacl1 | C3: 2.3.2-1build1.1 | D3: NOASSERTION | E3: Actively maintained | F3: 49059 | G3: 47269 | H3: =IF(F3="","",F3-TODAY()) -> 2786 | I3: Low | O3: Planned
A4: 2 | B4: adduser | C4: 3.137ubuntu1 | D4: NOASSERTION | E4: Actively maintained | F4: 49059 | G4: 47269 | H4: =IF(F4="","",F4-TODAY()) -> 2786 | I4: Low | O4: Planned
A5: 3 | B5: apt | C5: 2.8.3 | D5: NOASSERTION | E5: Actively maintained | F5: 49059 | G5: 47269 | H5: =IF(F5="","",F5-TODAY()) -> 2786 | I5: Low | O5: Planned
A6: 4 | B6: apt/apt-utils | C6: 2.8.3 | D6: NOASSERTION | E6: Actively maintained | F6: 49059 | G6: 47269 | H6: =IF(F6="","",F6-TODAY()) -> 2786 | I6: Low | O6: Planned
A7: 5 | B7: apt/libapt-pkg6.0t64 | C7: 2.8.3 | D7: NOASSERTION | E7: Actively maintained | F7: 49059 | G7: 47269 | H7: =IF(F7="","",F7-TODAY()) -> 2786 | I7: Low | O7: Planned
A8: 6 | B8: attr/libattr1 | C8: 1:2.5.2-1build1.1 | D8: NOASSERTION | E8: Actively maintained | F8: 49059 | G8: 47269 | H8: =IF(F8="","",F8-TODAY()) -> 2786 | I8: Low | O8: Planned
A9: 7 | B9: audit/libaudit-common | C9: 1:3.1.2-2.1build1.1 | D9: NOASSERTION | E9: Actively maintained | F9: 49059 | G9: 47269 | H9: =IF(F9="","",F9-TODAY()) -> 2786 | I9: Low | O9: Planned
A10: 8 | B10: audit/libaudit1 | C10: 1:3.1.2-2.1build1.1 | D10: NOASSERTION | E10: Actively maintained | F10: 49059 | G10: 47269 | H10: =IF(F10="","",F10-TODAY()) -> 2786 | I10: Low | O10: Planned
A11: 9 | B11: base-files | C11: 13ubuntu10.4 | D11: NOASSERTION | E11: Actively maintained | F11: 49059 | G11: 47269 | H11: =IF(F11="","",F11-TODAY()) -> 2786 | I11: Low | O11: Planned
A12: 10 | B12: base-passwd | C12: 3.6.3build1 | D12: NOASSERTION | E12: Actively maintained | F12: 49059 | G12: 47269 | H12: =IF(F12="","",F12-TODAY()) -> 2786 | I12: Low | O12: Planned
A13: 11 | B13: bash | C13: 5.2.21-2ubuntu4 | D13: NOASSERTION | E13: Actively maintained | F13: 49059 | G13: 47269 | H13: =IF(F13="","",F13-TODAY()) -> 2786 | I13: Low | O13: Planned
A14: 12 | B14: binutils/binutils-common | C14: 2.42-4ubuntu2.10 | D14: NOASSERTION | E14: Actively maintained | F14: 49059 | G14: 47269 | H14: =IF(F14="","",F14-TODAY()) -> 2786 | I14: Low | O14: Planned
... A275: 273 | B275: zlib/zlib1g | C275: 1:1.3.dfsg-3.1ubuntu2.1 | D275: NOASSERTION | E275: Actively maintained | F275: 49059 | G275: 47269 | H275: =IF(F275="","",F275-TODAY()) -> 2786 | I275: Low | O275: Planned
H276: =IF(F276="","",F276-TODAY())
H277: =IF(F277="","",F277-TODAY())
H278: =IF(F278="","",F278-TODAY())
H279: =IF(F279="","",F279-TODAY())
H280: =IF(F280="","",F280-TODAY())
H281: =IF(F281="","",F281-TODAY())
H282: =IF(F282="","",F282-TODAY())
H283: =IF(F283="","",F283-TODAY())
H284: =IF(F284="","",F284-TODAY())
H285: =IF(F285="","",F285-TODAY())
H286: =IF(F286="","",F286-TODAY())
H287: =IF(F287="","",F287-TODAY())
... H500: =IF(F500="","",F500-TODAY())

Sheet Supplier & Security Contacts
A1: Supplier & Security Contact Registry — supports Sec. 524B coordinated vulnerability disclosure (CVD) and supply-chain transparency expectations
A2: # | B2: Supplier / Manufacturer Legal Name | C2: Component(s) Supplied | D2: Security / PSIRT Contact Email | E2: Coordinated Vulnerability Disclosure (CVD) Policy URL | F2: Vulnerability Feed Subscribed | G2: Notes

Sheet FDA Compliance Dashboard
B2: FDA Compliance Dashboard — live, self-checking, computed from your data
B4: Composite FDA Readiness Score (average of every completeness row below) | C4: =AVERAGE(D8:D13,D17:D23,D27:D28) -> 0.34047619 | D4: =IF(C4>=0.85,"Ready",IF(C4>=0.5,"Partial — Gaps Remain","Not Ready")) -> Not Ready | F4: This is a completeness score for this template's data, not an FDA-issued figure — it flags gaps, it does not grant clearance.
B6: NTIA Minimum Elements
A7: # | B7: Element | C7: Category | D7: Completion | E7: Status | F7: How It's Calculated
A8: 1 | B8: Supplier Name | C8: NTIA min. | D8: =IFERROR(COUNTA('SBOM Components'!$D$3:$D$500)/COUNTA('SBOM Components'!$B$3:$B$500),0) -> 1 | E8: =IF(D8>=0.95,"Complete",IF(D8>0,"Partial","Missing")) -> Complete | F8: Non-blank ‘Supplier / Legal Entity Name’ cells ÷ components entered.
A9: 2 | B9: Version | C9: NTIA min. | D9: =IFERROR(COUNTA('SBOM Components'!$C$3:$C$500)/COUNTA('SBOM Components'!$B$3:$B$500),0) -> 0.92857143 | E9: =IF(D9>=0.95,"Complete",IF(D9>0,"Partial","Missing")) -> Partial | F9: Non-blank ‘Version’ cells ÷ components entered.
A10: 3 | B10: Unique Identifier (PURL/CPE/SWID) | C10: NTIA min. | D10: =IFERROR(COUNTA('SBOM Components'!$F$3:$F$500)/COUNTA('SBOM Components'!$B$3:$B$500),0) -> 1 | E10: =IF(D10>=0.95,"Complete",IF(D10>0,"Partial","Missing")) -> Complete | F10: Non-blank ‘Unique ID Value’ cells ÷ components entered.
A11: 4 | B11: Dependency Relationship (structured) | C11: NTIA min. | D11: =IFERROR(COUNTA('SBOM Components'!$G$3:$G$500)/COUNTA('SBOM Components'!$B$3:$B$500),0) -> 0 | E11: =IF(D11>=0.95,"Complete",IF(D11>0,"Partial","Missing")) -> Missing | F11: Non-blank ‘Dependency Type’ cells ÷ components entered.
A12: 5 | B12: SBOM Author (document-level) | C12: NTIA min. | D12: =IF('SBOM Metadata'!$C$18<>"",1,0) -> 0 | E12: =IF(D12>=0.95,"Complete",IF(D12>0,"Partial","Missing")) -> Missing | F12: 1 if ‘Author Email’ is completed on SBOM Metadata, else 0.
A13: 6 | B13: Timestamp (document-level) | C13: NTIA min. | D13: =IF('SBOM Metadata'!$C$19<>"",1,0) -> 1 | E13: =IF(D13>=0.95,"Complete",IF(D13>0,"Partial","Missing")) -> Complete | F13: 1 if ‘SBOM Timestamp’ is completed on SBOM Metadata, else 0.
B15: FDA Additional Elements (Sec. VII.C.3 / Premarket Expectations)
A16: # | B16: Element | C16: Category | D16: Completion | E16: Status | F16: How It's Calculated
A17: 1 | B17: End-of-Support (EOS) Date | C17: FDA Sec. VII.C.3 | D17: =IFERROR(COUNTA('SBOM Components'!$T$3:$T$500)/COUNTA('SBOM Components'!$B$3:$B$500),0) -> 0 | E17: =IF(D17>=0.95,"Complete",IF(D17>0,"Partial","Missing")) -> Missing | F17: Non-blank EOS Date cells ÷ components entered.
A18: 2 | B18: End-of-Life (EOL) Date | C18: FDA expectation | D18: =IFERROR(COUNTA('SBOM Components'!$U$3:$U$500)/COUNTA('SBOM Components'!$B$3:$B$500),0) -> 0 | E18: =IF(D18>=0.95,"Complete",IF(D18>0,"Partial","Missing")) -> Missing | F18: Non-blank EOL Date cells ÷ components entered.
A19: 3 | B19: Level of Support Known (not Unknown/blank) | C19: FDA Sec. VII.C.3 | D19: =IFERROR((COUNTA('SBOM Components'!$S$3:$S$500)-COUNTIF('SBOM Components'!$S$3:$S$500,"Unknown"))/COUNTA('SBOM Components'!$B$3:$B$500),0) -> 0 | E19: =IF(D19>=0.95,"Complete",IF(D19>0,"Partial","Missing")) -> Missing | F19: Components with a Level of Support other than ‘Unknown’ ÷ components entered.
A20: 4 | B20: Known Vulnerabilities Recorded | C20: FDA premarket expectation | D20: =IFERROR(COUNTA('SBOM Components'!$X$3:$X$500)/COUNTA('SBOM Components'!$B$3:$B$500),0) -> 0.17857143 | E20: =IF(D20>=0.95,"Complete",IF(D20>0,"Partial","Missing")) -> Partial | F20: Non-blank ‘Known Vulnerabilities’ cells ÷ components entered (0 CVEs found should still be marked ‘None known’).
A21: 5 | B21: Vulnerability Remediation Status / VEX Resolved | C21: FDA premarket expectation | D21: =IFERROR((COUNTA('Vulnerabilities & VEX'!$D$3:$D$500)-COUNTIF('Vulnerabilities & VEX'!$K$3:$K$500,"Under Investigation"))/COUNTA('Vulnerabilities & VEX'!$D$3:$D$500),0) -> 0 | E21: =IF(D21>=0.95,"Complete",IF(D21>0,"Partial","Missing")) -> Missing | F21: Vulnerabilities whose VEX Status has moved past ‘Under Investigation’ ÷ vulnerabilities logged.
A22: 6 | B22: Component Hash / Checksum Present | C22: Supply-chain integrity | D22: =IFERROR(COUNTA('SBOM Components'!$Z$3:$Z$500)/COUNTA('SBOM Components'!$B$3:$B$500),0) -> 0 | E22: =IF(D22>=0.95,"Complete",IF(D22>0,"Partial","Missing")) -> Missing | F22: Non-blank ‘Component Hash / Checksum’ cells ÷ components entered.
A23: 7 | B23: Cryptographic Signature Status Recorded | C23: Supply-chain integrity | D23: =IFERROR(COUNTA('SBOM Components'!$AA$3:$AA$500)/COUNTA('SBOM Components'!$B$3:$B$500),0) -> 0 | E23: =IF(D23>=0.95,"Complete",IF(D23>0,"Partial","Missing")) -> Missing | F23: Non-blank ‘Cryptographic Signature Status’ cells ÷ components entered.
B25: Supply-Chain Breadth
A26: # | B26: Element | C26: Category | D26: Completion | E26: Status | F26: How It's Calculated
A27: 1 | B27: OS / Container / Firmware / 3rd-Party Dependencies Logged | C27: Supply-chain transparency | D27: =IF(COUNTA('Environment & 3rd-Party Deps'!$C$3:$C$500)>0,1,0) -> 1 | E27: =IF(D27>=0.95,"Complete",IF(D27>0,"Partial","Missing")) -> Complete | F27: 1 if at least one row is entered on the Environment & 3rd-Party Deps tab.
A28: 2 | B28: Supplier Security Contacts / CVD Registered | C28: Sec. 524B — CVD | D28: =IF(COUNTA('Supplier & Security Contacts'!$B$3:$B$500)>0,1,0) -> 0 | E28: =IF(D28>=0.95,"Complete",IF(D28>0,"Partial","Missing")) -> Missing | F28: 1 if at least one row is entered on the Supplier & Security Contacts tab.
B31: Quick Stats (live counts)
B32: Metric | C32: Count | D32: Notes
B33: Total components listed | C33: ='SBOM Components'!$AF$1 -> 28
B34: Components PAST end-of-support | C34: ='SBOM Components'!$AF$2 -> 0
B35: Components with EOS within 12 months | C35: ='SBOM Components'!$AF$3 -> 0
B36: Components unsupported / unknown support status | C36: ='SBOM Components'!$AF$4 -> 28
B37: Total vulnerabilities logged | C37: ='Vulnerabilities & VEX'!$V$1 -> 120
B38: Open Critical / High vulnerabilities | C38: ='Vulnerabilities & VEX'!$V$2 -> 14
B39: Vulnerabilities missing a VEX justification | C39: ='Vulnerabilities & VEX'!$V$3 -> 120
B40: Vulnerabilities still 'Under Investigation' | C40: ='Vulnerabilities & VEX'!$V$4 -> 120
B41: Vulnerabilities missing a numeric CVSS score | C41: ='Vulnerabilities & VEX'!$V$5 -> 119
B42: Vulnerabilities missing a target resolution date | C42: ='Vulnerabilities & VEX'!$V$6 -> 120
